<error errorId="75083570-fcd9-4efa-b0b0-b9518cd762c8" host="KUYKENDALL-7040" type="System.Data.SqlClient.SqlException" message="Login failed for user 'DOESIS\KUYKENDALL-7040$'." source=".Net SqlClient Data Provider" detail="System.Data.Entity.Core.EntityException: The underlying provider failed on Open. ---&gt; System.Data.SqlClient.SqlException: Login failed for user 'DOESIS\KUYKENDALL-7040$'.&#xD;&#xA;   at System.Data.SqlClient.SqlInternalConnectionTds..ctor(DbConnectionPoolIdentity identity, SqlConnectionString connectionOptions, SqlCredential credential, Object providerInfo, String newPassword, SecureString newSecurePassword, Boolean redirectedUserInstance, SqlConnectionString userConnectionOptions, SessionData reconnectSessionData, DbConnectionPool pool, String accessToken, Boolean applyTransientFaultHandling)&#xD;&#xA;   at System.Data.SqlClient.SqlConnectionFactory.CreateConnection(DbConnectionOptions options, DbConnectionPoolKey poolKey, Object poolGroupProviderInfo, DbConnectionPool pool, DbConnection owningConnection, DbConnectionOptions userOptions)&#xD;&#xA;   at System.Data.ProviderBase.DbConnectionFactory.CreatePooledConnection(DbConnectionPool pool, DbConnection owningObject, DbConnectionOptions options, DbConnectionPoolKey poolKey, DbConnectionOptions userOptions)&#xD;&#xA;   at System.Data.ProviderBase.DbConnectionPool.CreateObject(DbConnection owningObject, DbConnectionOptions userOptions, DbConnectionInternal oldConnection)&#xD;&#xA;   at System.Data.ProviderBase.DbConnectionPool.UserCreateRequest(DbConnection owningObject, DbConnectionOptions userOptions, DbConnectionInternal oldConnection)&#xD;&#xA;   at System.Data.ProviderBase.DbConnectionPool.TryGetConnection(DbConnection owningObject, UInt32 waitForMultipleObjectsTimeout, Boolean allowCreate, Boolean onlyOneCheckConnection, DbConnectionOptions userOptions, DbConnectionInternal&amp; connection)&#xD;&#xA;   at System.Data.ProviderBase.DbConnectionPool.TryGetConnection(DbConnection owningObject, TaskCompletionSource`1 retry, DbConnectionOptions userOptions, DbConnectionInternal&amp; connection)&#xD;&#xA;   at System.Data.ProviderBase.DbConnectionFactory.TryGetConnection(DbConnection owningConnection, TaskCompletionSource`1 retry, DbConnectionOptions userOptions, DbConnectionInternal oldConnection, DbConnectionInternal&amp; connection)&#xD;&#xA;   at System.Data.ProviderBase.DbConnectionInternal.TryOpenConnectionInternal(DbConnection outerConnection, DbConnectionFactory connectionFactory, TaskCompletionSource`1 retry, DbConnectionOptions userOptions)&#xD;&#xA;   at System.Data.SqlClient.SqlConnection.TryOpenInner(TaskCompletionSource`1 retry)&#xD;&#xA;   at System.Data.SqlClient.SqlConnection.TryOpen(TaskCompletionSource`1 retry)&#xD;&#xA;   at System.Data.SqlClient.SqlConnection.Open()&#xD;&#xA;   at System.Data.Entity.Infrastructure.Interception.InternalDispatcher`1.Dispatch[TTarget,TInterceptionContext](TTarget target, Action`2 operation, TInterceptionContext interceptionContext, Action`3 executing, Action`3 executed)&#xD;&#xA;   at System.Data.Entity.Infrastructure.Interception.DbConnectionDispatcher.Open(DbConnection connection, DbInterceptionContext interceptionContext)&#xD;&#xA;   at System.Data.Entity.SqlServer.DefaultSqlExecutionStrategy.&lt;&gt;c__DisplayClass1.&lt;Execute&gt;b__0()&#xD;&#xA;   at System.Data.Entity.SqlServer.DefaultSqlExecutionStrategy.Execute[TResult](Func`1 operation)&#xD;&#xA;   at System.Data.Entity.Core.EntityClient.EntityConnection.Open()&#xD;&#xA;   --- End of inner exception stack trace ---&#xD;&#xA;   at System.Data.Entity.Core.EntityClient.EntityConnection.Open()&#xD;&#xA;   at System.Data.Entity.Core.Objects.ObjectContext.EnsureConnection(Boolean shouldMonitorTransactions)&#xD;&#xA;   at System.Data.Entity.Core.Objects.ObjectContext.ExecuteInTransaction[T](Func`1 func, IDbExecutionStrategy executionStrategy, Boolean startLocalTransaction, Boolean releaseConnectionOnSuccess)&#xD;&#xA;   at System.Data.Entity.Core.Objects.ObjectQuery`1.&lt;&gt;c__DisplayClass7.&lt;GetResults&gt;b__5()&#xD;&#xA;   at System.Data.Entity.SqlServer.DefaultSqlExecutionStrategy.Execute[TResult](Func`1 operation)&#xD;&#xA;   at System.Data.Entity.Core.Objects.ObjectQuery`1.GetResults(Nullable`1 forMergeOption)&#xD;&#xA;   at System.Data.Entity.Core.Objects.ObjectQuery`1.&lt;System.Collections.Generic.IEnumerable&lt;T&gt;.GetEnumerator&gt;b__0()&#xD;&#xA;   at System.Data.Entity.Internal.LazyEnumerator`1.MoveNext()&#xD;&#xA;   at System.Linq.Enumerable.First[TSource](IEnumerable`1 source)&#xD;&#xA;   at DEMO.Services.DEMOService.GetWizardModel(String WizardCode, Int32 ID) in d:\Demos\Wizard\Scaffold\MT\DEMO.Services\DEMOService.cs:line 36&#xD;&#xA;   at DEMO.API.Controllers.DemoWizardController.Get(Int32 ID) in d:\Demos\Wizard\Scaffold\MT\DEMO.API\Controllers\DemoWizardController.cs:line 26&#xD;&#xA;   at lambda_method(Closure , Object , Object[] )&#xD;&#xA;   at System.Web.Http.Controllers.ReflectedHttpActionDescriptor.ActionExecutor.&lt;&gt;c__DisplayClass10.&lt;GetExecutor&gt;b__9(Object instance, Object[] methodParameters)&#xD;&#xA;   at System.Web.Http.Controllers.ReflectedHttpActionDescriptor.ExecuteAsync(HttpControllerContext controllerContext, IDictionary`2 arguments, CancellationToken cancellationToken)&#xD;&#xA;--- End of stack trace from previous location where exception was thrown ---&#xD;&#xA;   at System.Runtime.CompilerServices.TaskAwaiter.ThrowForNonSuccess(Task task)&#xD;&#xA;   at System.Runtime.CompilerServices.TaskAwaiter.HandleNonSuccessAndDebuggerNotification(Task task)&#xD;&#xA;   at System.Web.Http.Controllers.ApiControllerActionInvoker.&lt;InvokeActionAsyncCore&gt;d__0.MoveNext()&#xD;&#xA;--- End of stack trace from previous location where exception was thrown ---&#xD;&#xA;   at System.Runtime.CompilerServices.TaskAwaiter.ThrowForNonSuccess(Task task)&#xD;&#xA;   at System.Runtime.CompilerServices.TaskAwaiter.HandleNonSuccessAndDebuggerNotification(Task task)&#xD;&#xA;   at System.Web.Http.Controllers.ActionFilterResult.&lt;ExecuteAsync&gt;d__2.MoveNext()&#xD;&#xA;--- End of stack trace from previous location where exception was thrown ---&#xD;&#xA;   at System.Runtime.CompilerServices.TaskAwaiter.ThrowForNonSuccess(Task task)&#xD;&#xA;   at System.Runtime.CompilerServices.TaskAwaiter.HandleNonSuccessAndDebuggerNotification(Task task)&#xD;&#xA;   at System.Web.Http.Controllers.AuthenticationFilterResult.&lt;ExecuteAsync&gt;d__0.MoveNext()&#xD;&#xA;--- End of stack trace from previous location where exception was thrown ---&#xD;&#xA;   at System.Runtime.CompilerServices.TaskAwaiter.ThrowForNonSuccess(Task task)&#xD;&#xA;   at System.Runtime.CompilerServices.TaskAwaiter.HandleNonSuccessAndDebuggerNotification(Task task)&#xD;&#xA;   at System.Web.Http.Controllers.ExceptionFilterResult.&lt;ExecuteAsync&gt;d__0.MoveNext()" time="2017-08-07T18:56:50.8355703Z" />